[2024-03-28T21:00:44.789+0000] {taskinstance.py:1159} INFO - Dependencies all met for dep_context=non-requeueable deps ti=<TaskInstance: my_daily_dag.transformar_data manual__2024-03-28T20:58:37.620692+00:00 [queued]>
[2024-03-28T21:00:44.800+0000] {taskinstance.py:1159} INFO - Dependencies all met for dep_context=requeueable deps ti=<TaskInstance: my_daily_dag.transformar_data manual__2024-03-28T20:58:37.620692+00:00 [queued]>
[2024-03-28T21:00:44.801+0000] {taskinstance.py:1361} INFO - Starting attempt 1 of 4
[2024-03-28T21:00:44.818+0000] {taskinstance.py:1382} INFO - Executing <Task(PythonOperator): transformar_data> on 2024-03-28 20:58:37.620692+00:00
[2024-03-28T21:00:44.825+0000] {standard_task_runner.py:57} INFO - Started process 203 to run task
[2024-03-28T21:00:44.827+0000] {standard_task_runner.py:84} INFO - Running: ['***', 'tasks', 'run', 'my_daily_dag', 'transformar_data', 'manual__2024-03-28T20:58:37.620692+00:00', '--job-id', '18', '--raw', '--subdir', 'DAGS_FOLDER/data_ingestion_daily.py', '--cfg-path', '/tmp/tmpdbw2pfro']
[2024-03-28T21:00:44.828+0000] {standard_task_runner.py:85} INFO - Job 18: Subtask transformar_data
[2024-03-28T21:00:44.895+0000] {task_command.py:416} INFO - Running <TaskInstance: my_daily_dag.transformar_data manual__2024-03-28T20:58:37.620692+00:00 [running]> on host b4105c9891da
[2024-03-28T21:00:44.992+0000] {taskinstance.py:1662} INFO - Exporting env vars: AIRFLOW_CTX_DAG_OWNER='***' AIRFLOW_CTX_DAG_ID='my_daily_dag' AIRFLOW_CTX_TASK_ID='transformar_data' AIRFLOW_CTX_EXECUTION_DATE='2024-03-28T20:58:37.620692+00:00' AIRFLOW_CTX_TRY_NUMBER='1' AIRFLOW_CTX_DAG_RUN_ID='manual__2024-03-28T20:58:37.620692+00:00'
[2024-03-28T21:00:52.296+0000] {logging_mixin.py:154} INFO - Conectado a Redshift con Ã©xito!
[2024-03-28T21:00:52.956+0000] {logging_mixin.py:154} INFO - No es posible crear tabla agencies en DB: 
[2024-03-28T21:00:52.957+0000] {logging_mixin.py:154} INFO - (psycopg2.errors.InternalError_) could not open relation with OID 966488

[SQL: 
            DROP TABLE camilagonzalezalejo02_coderhouse.agencies;
            create table if not exists  camilagonzalezalejo02_coderhouse.agencies
            (       	
            agency_id INTEGER,
            agency_name VARCHAR(100)
            )
        DISTSTYLE ALL
        sortkey(agency_id)
        ]
(Background on this error at: https://sqlalche.me/e/14/2j85)
[2024-03-28T21:00:53.737+0000] {logging_mixin.py:154} INFO - Tabla bus_positions creada con exito en DB
[2024-03-28T21:00:54.436+0000] {logging_mixin.py:154} INFO - Tabla ecobici_stations creada con exito en DB
[2024-03-28T21:00:55.122+0000] {logging_mixin.py:154} INFO - Tabla ecobici_stations_status creada con exito en DB
[2024-03-28T21:00:55.123+0000] {utils.py:56} INFO - Cargando datos en la base de datos...
[2024-03-28T21:00:55.835+0000] {logging_mixin.py:154} INFO - Datos cargados exitosamente en la base de datos
[2024-03-28T21:00:55.836+0000] {utils.py:56} INFO - Cargando datos en la base de datos...
[2024-03-28T21:01:20.095+0000] {local_task_job_runner.py:294} WARNING - State of this instance has been externally set to None. Terminating instance.
[2024-03-28T21:01:20.099+0000] {process_utils.py:131} INFO - Sending 15 to group 203. PIDs of all processes in the group: [203]
[2024-03-28T21:01:20.099+0000] {process_utils.py:86} INFO - Sending the signal 15 to group 203
[2024-03-28T21:01:20.244+0000] {taskinstance.py:1632} ERROR - Received SIGTERM. Terminating subprocesses.
[2024-03-28T21:01:20.245+0000] {logging_mixin.py:154} INFO - Error al insertar el registro 31: Task received SIGTERM signal
[2024-03-28T21:01:22.350+0000] {logging_mixin.py:154} INFO - Error al insertar el registro 34: (psycopg2.errors.InternalError_) could not open relation with OID 966500

[SQL: INSERT INTO bus_positions VALUES (%(id)s, %(agency_id)s, %(route_id)s, %(latitude)s, %(longitude)s, %(speed)s, %(timestamp)s, %(route_short_name)s, %(trip_headsign)s)]
[parameters: {'id': '23913', 'agency_id': 145, 'route_id': '1295', 'latitude': -34.81492, 'longitude': -58.25498, 'speed': 9.166666, 'timestamp': Timestamp('2024-03-28 20:59:40'), 'route_short_name': '324R9F', 'trip_headsign': 'a Pilar x Ford'}]
(Background on this error at: https://sqlalche.me/e/14/2j85)
[2024-03-28T21:01:43.350+0000] {local_task_job_runner.py:115} ERROR - Received SIGTERM. Terminating subprocesses
[2024-03-28T21:01:43.353+0000] {process_utils.py:131} INFO - Sending 15 to group 203. PIDs of all processes in the group: [203]
[2024-03-28T21:01:43.385+0000] {process_utils.py:86} INFO - Sending the signal 15 to group 203
[2024-03-28T21:01:43.694+0000] {taskinstance.py:1632} ERROR - Received SIGTERM. Terminating subprocesses.
[2024-03-28T21:01:43.909+0000] {logging_mixin.py:154} INFO - Error al insertar el registro 59: Task received SIGTERM signal
